2024-07-29 13:15:24,786 - backend.services.category_services - ERROR - Category Insert Service Exception: Class 'sqlalchemy.sql.schema.Table' is not mapped
Traceback (most recent call last):
  File "C:\ProgramData\Anaconda3\lib\site-packages\sqlalchemy\orm\session.py", line 3128, in refresh
    state = attributes.instance_state(instance)
AttributeError: 'Table' object has no attribute '_sa_instance_state'

The above exception was the direct cause of the following exception:

Traceback (most recent call last):
  File "D:\Training\FastAPI\Structural FastAPI\backend\services\category_services.py", line 57, in admin_insert_category
    category_dao.create_category(category_vo)
  File "D:\Training\FastAPI\Structural FastAPI\backend\dao\category_dao.py", line 11, in create_category
    sql_dynamic.insert_data('category_table', category)
  File "D:\Training\FastAPI\Structural FastAPI\backend\sql_dynamic.py", line 30, in insert_data
    db.refresh(table)
  File "C:\ProgramData\Anaconda3\lib\site-packages\sqlalchemy\orm\session.py", line 3130, in refresh
    raise exc.UnmappedInstanceError(instance) from err
sqlalchemy.orm.exc.UnmappedInstanceError: Class 'sqlalchemy.sql.schema.Table' is not mapped
2024-07-29 13:15:50,719 - backend.services.category_services - ERROR - Category Insert Service Exception: refresh() missing 1 required positional argument: 'instance'
Traceback (most recent call last):
  File "D:\Training\FastAPI\Structural FastAPI\backend\services\category_services.py", line 57, in admin_insert_category
    category_dao.create_category(category_vo)
  File "D:\Training\FastAPI\Structural FastAPI\backend\dao\category_dao.py", line 11, in create_category
    sql_dynamic.insert_data('category_table', category)
  File "D:\Training\FastAPI\Structural FastAPI\backend\sql_dynamic.py", line 30, in insert_data
    db.refresh()
TypeError: refresh() missing 1 required positional argument: 'instance'
2024-07-29 13:23:04,979 - backend.services.category_services - ERROR - Category Delete Service Exception: Class 'sqlalchemy.orm.decl_api.DeclarativeMeta' is not mapped; was a class (backend.vo.category_vo.CategoryVO) supplied where an instance was required?
Traceback (most recent call last):
  File "C:\ProgramData\Anaconda3\lib\site-packages\sqlalchemy\orm\session.py", line 3128, in refresh
    state = attributes.instance_state(instance)
AttributeError: type object 'CategoryVO' has no attribute '_sa_instance_state'

The above exception was the direct cause of the following exception:

Traceback (most recent call last):
  File "D:\Training\FastAPI\Structural FastAPI\backend\services\category_services.py", line 132, in admin_delete_category
    category_vo_list = category_dao.read_category_mutable(category_id)
  File "D:\Training\FastAPI\Structural FastAPI\backend\dao\category_dao.py", line 30, in read_category_mutable
    db.refresh(CategoryVO)
  File "C:\ProgramData\Anaconda3\lib\site-packages\sqlalchemy\orm\session.py", line 3130, in refresh
    raise exc.UnmappedInstanceError(instance) from err
sqlalchemy.orm.exc.UnmappedInstanceError: Class 'sqlalchemy.orm.decl_api.DeclarativeMeta' is not mapped; was a class (backend.vo.category_vo.CategoryVO) supplied where an instance was required?
2024-07-29 13:24:54,312 - backend.services.category_services - ERROR - Category Delete Service Exception: Class 'sqlalchemy.orm.decl_api.DeclarativeMeta' is not mapped; was a class (backend.vo.category_vo.CategoryVO) supplied where an instance was required?
Traceback (most recent call last):
  File "C:\ProgramData\Anaconda3\lib\site-packages\sqlalchemy\orm\session.py", line 3128, in refresh
    state = attributes.instance_state(instance)
AttributeError: type object 'CategoryVO' has no attribute '_sa_instance_state'

The above exception was the direct cause of the following exception:

Traceback (most recent call last):
  File "D:\Training\FastAPI\Structural FastAPI\backend\services\category_services.py", line 132, in admin_delete_category
    category_vo_list = category_dao.read_category_mutable(category_id)
  File "D:\Training\FastAPI\Structural FastAPI\backend\dao\category_dao.py", line 31, in read_category_mutable
    db.refresh(category_vo)
  File "C:\ProgramData\Anaconda3\lib\site-packages\sqlalchemy\orm\session.py", line 3130, in refresh
    raise exc.UnmappedInstanceError(instance) from err
sqlalchemy.orm.exc.UnmappedInstanceError: Class 'sqlalchemy.orm.decl_api.DeclarativeMeta' is not mapped; was a class (backend.vo.category_vo.CategoryVO) supplied where an instance was required?
2024-07-29 13:25:14,245 - backend.services.category_services - ERROR - Category Delete Service Exception: Class 'sqlalchemy.orm.decl_api.DeclarativeMeta' is not mapped; was a class (backend.vo.category_vo.CategoryVO) supplied where an instance was required?
Traceback (most recent call last):
  File "C:\ProgramData\Anaconda3\lib\site-packages\sqlalchemy\orm\session.py", line 3128, in refresh
    state = attributes.instance_state(instance)
AttributeError: type object 'CategoryVO' has no attribute '_sa_instance_state'

The above exception was the direct cause of the following exception:

Traceback (most recent call last):
  File "D:\Training\FastAPI\Structural FastAPI\backend\services\category_services.py", line 132, in admin_delete_category
    category_vo_list = category_dao.read_category_mutable(category_id)
  File "D:\Training\FastAPI\Structural FastAPI\backend\dao\category_dao.py", line 32, in read_category_mutable
    db.refresh(category_vo)
  File "C:\ProgramData\Anaconda3\lib\site-packages\sqlalchemy\orm\session.py", line 3130, in refresh
    raise exc.UnmappedInstanceError(instance) from err
sqlalchemy.orm.exc.UnmappedInstanceError: Class 'sqlalchemy.orm.decl_api.DeclarativeMeta' is not mapped; was a class (backend.vo.category_vo.CategoryVO) supplied where an instance was required?
2024-07-29 13:25:33,445 - backend.services.category_services - ERROR - Category Delete Service Exception: Class 'sqlalchemy.orm.decl_api.DeclarativeMeta' is not mapped; was a class (backend.vo.category_vo.CategoryVO) supplied where an instance was required?
Traceback (most recent call last):
  File "C:\ProgramData\Anaconda3\lib\site-packages\sqlalchemy\orm\session.py", line 3128, in refresh
    state = attributes.instance_state(instance)
AttributeError: type object 'CategoryVO' has no attribute '_sa_instance_state'

The above exception was the direct cause of the following exception:

Traceback (most recent call last):
  File "D:\Training\FastAPI\Structural FastAPI\backend\services\category_services.py", line 132, in admin_delete_category
    category_vo_list = category_dao.read_category_mutable(category_id)
  File "D:\Training\FastAPI\Structural FastAPI\backend\dao\category_dao.py", line 32, in read_category_mutable
    db.refresh(category_vo)
  File "C:\ProgramData\Anaconda3\lib\site-packages\sqlalchemy\orm\session.py", line 3130, in refresh
    raise exc.UnmappedInstanceError(instance) from err
sqlalchemy.orm.exc.UnmappedInstanceError: Class 'sqlalchemy.orm.decl_api.DeclarativeMeta' is not mapped; was a class (backend.vo.category_vo.CategoryVO) supplied where an instance was required?
2024-07-29 14:00:41,083 - backend.services.category_services - ERROR - Category Delete Service Exception: 'function' object has no attribute 'get'
Traceback (most recent call last):
  File "D:\Training\FastAPI\Structural FastAPI\backend\services\category_services.py", line 132, in admin_delete_category
    category_vo_list = category_dao.read_category_mutable(category_id)
  File "D:\Training\FastAPI\Structural FastAPI\backend\dao\category_dao.py", line 30, in read_category_mutable
    category_vo_list = db.query.get(CategoryVO, update_category_id)
AttributeError: 'function' object has no attribute 'get'
2024-07-29 14:01:51,197 - backend.services.category_services - ERROR - Category Delete Service Exception: get() got an unexpected keyword argument 'category_id'
Traceback (most recent call last):
  File "D:\Training\FastAPI\Structural FastAPI\backend\services\category_services.py", line 132, in admin_delete_category
    category_vo_list = category_dao.read_category_mutable(category_id)
  File "D:\Training\FastAPI\Structural FastAPI\backend\dao\category_dao.py", line 30, in read_category_mutable
    category_vo_list = db.query(CategoryVO).get(
TypeError: get() got an unexpected keyword argument 'category_id'
2024-07-29 14:13:47,604 - backend.services.category_services - ERROR - Category Update Service Exception: 'list' object has no attribute 'is_deleted'
Traceback (most recent call last):
  File "D:\Training\FastAPI\Structural FastAPI\backend\services\category_services.py", line 166, in admin_update_category
    if category_vo_list and not category_vo_list.is_deleted:
AttributeError: 'list' object has no attribute 'is_deleted'
2024-07-29 14:14:18,703 - backend.services.category_services - ERROR - Category Update Service Exception: 'list' object has no attribute 'is_deleted'
Traceback (most recent call last):
  File "D:\Training\FastAPI\Structural FastAPI\backend\services\category_services.py", line 166, in admin_update_category
    if category_vo_list and not category_vo_list.is_deleted:
AttributeError: 'list' object has no attribute 'is_deleted'
2024-07-29 14:14:47,850 - backend.services.category_services - ERROR - Category Update Service Exception: 'list' object has no attribute 'is_deleted'
Traceback (most recent call last):
  File "D:\Training\FastAPI\Structural FastAPI\backend\services\category_services.py", line 164, in admin_update_category
    category_vo_list = category_dao.read_category_mutable(update_category_id)
  File "D:\Training\FastAPI\Structural FastAPI\backend\dao\category_dao.py", line 31, in read_category_mutable
    print(category_vo_list.is_deleted)
AttributeError: 'list' object has no attribute 'is_deleted'
2024-07-29 14:15:16,170 - backend.services.category_services - ERROR - Category Update Service Exception: 'list' object has no attribute 'is_deleted'
Traceback (most recent call last):
  File "D:\Training\FastAPI\Structural FastAPI\backend\services\category_services.py", line 166, in admin_update_category
    if category_vo_list and not category_vo_list.is_deleted:
AttributeError: 'list' object has no attribute 'is_deleted'
2024-07-29 14:15:53,869 - backend.services.category_services - ERROR - Category Update Service Exception: 'list' object has no attribute 'is_deleted'
Traceback (most recent call last):
  File "D:\Training\FastAPI\Structural FastAPI\backend\services\category_services.py", line 166, in admin_update_category
    if category_vo_list and not category_vo_list.is_deleted:
AttributeError: 'list' object has no attribute 'is_deleted'
2024-07-29 14:16:55,744 - backend.services.category_services - ERROR - Category Update Service Exception: list index out of range
Traceback (most recent call last):
  File "D:\Training\FastAPI\Structural FastAPI\backend\services\category_services.py", line 164, in admin_update_category
    category_vo_list = category_dao.read_category_mutable(update_category_id)
  File "D:\Training\FastAPI\Structural FastAPI\backend\dao\category_dao.py", line 31, in read_category_mutable
    return category_vo_list[0]
IndexError: list index out of range
2024-07-29 14:18:12,397 - backend.services.category_services - ERROR - Category Update Service Exception: list index out of range
Traceback (most recent call last):
  File "D:\Training\FastAPI\Structural FastAPI\backend\services\category_services.py", line 164, in admin_update_category
    category_vo_list = category_dao.read_category_mutable(update_category_id)
  File "D:\Training\FastAPI\Structural FastAPI\backend\dao\category_dao.py", line 31, in read_category_mutable
    print(category_vo_list[0])
IndexError: list index out of range
2024-07-29 14:20:15,865 - backend.services.category_services - ERROR - Category Update Service Exception: list index out of range
Traceback (most recent call last):
  File "D:\Training\FastAPI\Structural FastAPI\backend\services\category_services.py", line 164, in admin_update_category
    category_vo_list = category_dao.read_category_mutable(update_category_id)
  File "D:\Training\FastAPI\Structural FastAPI\backend\dao\category_dao.py", line 32, in read_category_mutable
    print(category_vo_list[0])
IndexError: list index out of range
2024-07-29 14:21:08,586 - backend.services.category_services - ERROR - Category Update Service Exception: list index out of range
Traceback (most recent call last):
  File "D:\Training\FastAPI\Structural FastAPI\backend\services\category_services.py", line 164, in admin_update_category
    category_vo_list = category_dao.read_category_mutable(update_category_id)
  File "D:\Training\FastAPI\Structural FastAPI\backend\dao\category_dao.py", line 31, in read_category_mutable
    print(category_vo_list[0])
IndexError: list index out of range
2024-07-29 14:46:10,959 - backend.services.category_services - ERROR - Category Delete Service Exception: Boolean value of this clause is not defined
Traceback (most recent call last):
  File "D:\Training\FastAPI\Structural FastAPI\backend\services\category_services.py", line 132, in admin_delete_category
    category_vo_list = category_dao.read_category_mutable(category_id)
  File "D:\Training\FastAPI\Structural FastAPI\backend\dao\category_dao.py", line 36, in read_category_mutable
    category_vo_list = sql_dynamic.view_data_mutable('category_table', update_category_id)
  File "D:\Training\FastAPI\Structural FastAPI\backend\sql_dynamic.py", line 119, in view_data_mutable
    if table:
  File "C:\ProgramData\Anaconda3\lib\site-packages\sqlalchemy\sql\elements.py", line 748, in __bool__
    raise TypeError("Boolean value of this clause is not defined")
TypeError: Boolean value of this clause is not defined
2024-07-29 14:51:52,897 - backend.services.category_services - ERROR - Category Delete Service Exception: can't set attribute
Traceback (most recent call last):
  File "D:\Training\FastAPI\Structural FastAPI\backend\services\category_services.py", line 134, in admin_delete_category
    category_vo_list.is_deleted = True
  File "C:\ProgramData\Anaconda3\lib\site-packages\sqlalchemy\engine\row.py", line 81, in __setattr__
    raise AttributeError("can't set attribute")
AttributeError: can't set attribute
2024-07-29 15:06:54,181 - backend.services.category_services - ERROR - Category Delete Service Exception: Class 'builtins.NoneType' is not mapped
Traceback (most recent call last):
  File "C:\ProgramData\Anaconda3\lib\site-packages\sqlalchemy\orm\session.py", line 3128, in refresh
    state = attributes.instance_state(instance)
AttributeError: 'NoneType' object has no attribute '_sa_instance_state'

The above exception was the direct cause of the following exception:

Traceback (most recent call last):
  File "D:\Training\FastAPI\Structural FastAPI\backend\services\category_services.py", line 132, in admin_delete_category
    category_vo_list = category_dao.read_category_mutable(category_id)
  File "D:\Training\FastAPI\Structural FastAPI\backend\dao\category_dao.py", line 32, in read_category_mutable
    db.refresh(category_vo_list)
  File "C:\ProgramData\Anaconda3\lib\site-packages\sqlalchemy\orm\session.py", line 3130, in refresh
    raise exc.UnmappedInstanceError(instance) from err
sqlalchemy.orm.exc.UnmappedInstanceError: Class 'builtins.NoneType' is not mapped
2024-07-29 15:07:38,068 - backend.services.category_services - ERROR - Category Delete Service Exception: Class 'builtins.NoneType' is not mapped
Traceback (most recent call last):
  File "C:\ProgramData\Anaconda3\lib\site-packages\sqlalchemy\orm\session.py", line 3128, in refresh
    state = attributes.instance_state(instance)
AttributeError: 'NoneType' object has no attribute '_sa_instance_state'

The above exception was the direct cause of the following exception:

Traceback (most recent call last):
  File "D:\Training\FastAPI\Structural FastAPI\backend\services\category_services.py", line 132, in admin_delete_category
    category_vo_list = category_dao.read_category_mutable(category_id)
  File "D:\Training\FastAPI\Structural FastAPI\backend\dao\category_dao.py", line 32, in read_category_mutable
    db.refresh(category_vo_list)
  File "C:\ProgramData\Anaconda3\lib\site-packages\sqlalchemy\orm\session.py", line 3130, in refresh
    raise exc.UnmappedInstanceError(instance) from err
sqlalchemy.orm.exc.UnmappedInstanceError: Class 'builtins.NoneType' is not mapped
2024-07-29 15:09:45,074 - backend.services.category_services - ERROR - Category Delete Service Exception: Class 'builtins.NoneType' is not mapped
Traceback (most recent call last):
  File "C:\ProgramData\Anaconda3\lib\site-packages\sqlalchemy\orm\session.py", line 3128, in refresh
    state = attributes.instance_state(instance)
AttributeError: 'NoneType' object has no attribute '_sa_instance_state'

The above exception was the direct cause of the following exception:

Traceback (most recent call last):
  File "D:\Training\FastAPI\Structural FastAPI\backend\services\category_services.py", line 132, in admin_delete_category
    category_vo_list = category_dao.read_category_mutable(category_id)
  File "D:\Training\FastAPI\Structural FastAPI\backend\dao\category_dao.py", line 32, in read_category_mutable
    db.refresh(category_vo_list)
  File "C:\ProgramData\Anaconda3\lib\site-packages\sqlalchemy\orm\session.py", line 3130, in refresh
    raise exc.UnmappedInstanceError(instance) from err
sqlalchemy.orm.exc.UnmappedInstanceError: Class 'builtins.NoneType' is not mapped
2024-07-29 15:45:28,734 - backend.services.category_services - ERROR - Category Delete Service Exception: 'dict' object has no attribute 'is_deleted'
Traceback (most recent call last):
  File "D:\Training\FastAPI\Structural FastAPI\backend\services\category_services.py", line 133, in admin_delete_category
    if category_vo_list and not category_vo_list.is_deleted:
AttributeError: 'dict' object has no attribute 'is_deleted'
2024-07-29 15:46:35,264 - backend.services.category_services - ERROR - Category Delete Service Exception: 'dict' object has no attribute 'is_deleted'
Traceback (most recent call last):
  File "D:\Training\FastAPI\Structural FastAPI\backend\services\category_services.py", line 133, in admin_delete_category
    if category_vo_list and not category_vo_list.is_deleted:
AttributeError: 'dict' object has no attribute 'is_deleted'
2024-07-29 16:24:28,115 - backend.services.category_services - ERROR - Category Insert Service Exception: Instance '<CategoryVO at 0x20626af0880>' is not persistent within this Session
Traceback (most recent call last):
  File "D:\Training\FastAPI\Structural FastAPI\backend\services\category_services.py", line 57, in admin_insert_category
    category_dao.create_category(category_vo)
  File "D:\Training\FastAPI\Structural FastAPI\backend\dao\category_dao.py", line 11, in create_category
    sql_dynamic.insert_data('category_table', category)
  File "D:\Training\FastAPI\Structural FastAPI\backend\sql_dynamic.py", line 32, in insert_data
    db.refresh(data)
  File "C:\ProgramData\Anaconda3\lib\site-packages\sqlalchemy\orm\session.py", line 3132, in refresh
    self._expire_state(state, attribute_names)
  File "C:\ProgramData\Anaconda3\lib\site-packages\sqlalchemy\orm\session.py", line 3258, in _expire_state
    self._validate_persistent(state)
  File "C:\ProgramData\Anaconda3\lib\site-packages\sqlalchemy\orm\session.py", line 4127, in _validate_persistent
    raise sa_exc.InvalidRequestError(
sqlalchemy.exc.InvalidRequestError: Instance '<CategoryVO at 0x20626af0880>' is not persistent within this Session
2024-07-29 16:25:51,564 - backend.services.category_services - ERROR - Category Read Service Exception: Class 'builtins.list' is not mapped
Traceback (most recent call last):
  File "C:\ProgramData\Anaconda3\lib\site-packages\sqlalchemy\orm\session.py", line 3128, in refresh
    state = attributes.instance_state(instance)
AttributeError: 'list' object has no attribute '_sa_instance_state'

The above exception was the direct cause of the following exception:

Traceback (most recent call last):
  File "D:\Training\FastAPI\Structural FastAPI\backend\services\category_services.py", line 90, in admin_read_categories
    category_data = category_dao.read_categories()
  File "D:\Training\FastAPI\Structural FastAPI\backend\dao\category_dao.py", line 22, in read_categories
    category_data = sql_dynamic.view_data_all('category_table')
  File "D:\Training\FastAPI\Structural FastAPI\backend\sql_dynamic.py", line 48, in view_data_all
    db.refresh(view_stmt)
  File "C:\ProgramData\Anaconda3\lib\site-packages\sqlalchemy\orm\session.py", line 3130, in refresh
    raise exc.UnmappedInstanceError(instance) from err
sqlalchemy.orm.exc.UnmappedInstanceError: Class 'builtins.list' is not mapped
2024-07-29 16:26:03,780 - backend.services.category_services - ERROR - Category Read Service Exception: Class 'builtins.list' is not mapped
Traceback (most recent call last):
  File "C:\ProgramData\Anaconda3\lib\site-packages\sqlalchemy\orm\session.py", line 3128, in refresh
    state = attributes.instance_state(instance)
AttributeError: 'list' object has no attribute '_sa_instance_state'

The above exception was the direct cause of the following exception:

Traceback (most recent call last):
  File "D:\Training\FastAPI\Structural FastAPI\backend\services\category_services.py", line 90, in admin_read_categories
    category_data = category_dao.read_categories()
  File "D:\Training\FastAPI\Structural FastAPI\backend\dao\category_dao.py", line 22, in read_categories
    category_data = sql_dynamic.view_data_all('category_table')
  File "D:\Training\FastAPI\Structural FastAPI\backend\sql_dynamic.py", line 48, in view_data_all
    db.refresh(view_stmt)
  File "C:\ProgramData\Anaconda3\lib\site-packages\sqlalchemy\orm\session.py", line 3130, in refresh
    raise exc.UnmappedInstanceError(instance) from err
sqlalchemy.orm.exc.UnmappedInstanceError: Class 'builtins.list' is not mapped
2024-07-29 16:26:06,868 - backend.services.category_services - ERROR - Category Read Service Exception: Class 'builtins.list' is not mapped
Traceback (most recent call last):
  File "C:\ProgramData\Anaconda3\lib\site-packages\sqlalchemy\orm\session.py", line 3128, in refresh
    state = attributes.instance_state(instance)
AttributeError: 'list' object has no attribute '_sa_instance_state'

The above exception was the direct cause of the following exception:

Traceback (most recent call last):
  File "D:\Training\FastAPI\Structural FastAPI\backend\services\category_services.py", line 90, in admin_read_categories
    category_data = category_dao.read_categories()
  File "D:\Training\FastAPI\Structural FastAPI\backend\dao\category_dao.py", line 22, in read_categories
    category_data = sql_dynamic.view_data_all('category_table')
  File "D:\Training\FastAPI\Structural FastAPI\backend\sql_dynamic.py", line 48, in view_data_all
    db.refresh(view_stmt)
  File "C:\ProgramData\Anaconda3\lib\site-packages\sqlalchemy\orm\session.py", line 3130, in refresh
    raise exc.UnmappedInstanceError(instance) from err
sqlalchemy.orm.exc.UnmappedInstanceError: Class 'builtins.list' is not mapped
2024-07-29 16:26:16,180 - backend.services.category_services - ERROR - Category Read Service Exception: Class 'builtins.list' is not mapped
Traceback (most recent call last):
  File "C:\ProgramData\Anaconda3\lib\site-packages\sqlalchemy\orm\session.py", line 3128, in refresh
    state = attributes.instance_state(instance)
AttributeError: 'list' object has no attribute '_sa_instance_state'

The above exception was the direct cause of the following exception:

Traceback (most recent call last):
  File "D:\Training\FastAPI\Structural FastAPI\backend\services\category_services.py", line 90, in admin_read_categories
    category_data = category_dao.read_categories()
  File "D:\Training\FastAPI\Structural FastAPI\backend\dao\category_dao.py", line 22, in read_categories
    category_data = sql_dynamic.view_data_all('category_table')
  File "D:\Training\FastAPI\Structural FastAPI\backend\sql_dynamic.py", line 48, in view_data_all
    db.refresh(view_stmt)
  File "C:\ProgramData\Anaconda3\lib\site-packages\sqlalchemy\orm\session.py", line 3130, in refresh
    raise exc.UnmappedInstanceError(instance) from err
sqlalchemy.orm.exc.UnmappedInstanceError: Class 'builtins.list' is not mapped
2024-07-29 16:26:29,713 - backend.services.category_services - ERROR - Category Read Service Exception: Class 'builtins.list' is not mapped
Traceback (most recent call last):
  File "C:\ProgramData\Anaconda3\lib\site-packages\sqlalchemy\orm\session.py", line 3128, in refresh
    state = attributes.instance_state(instance)
AttributeError: 'list' object has no attribute '_sa_instance_state'

The above exception was the direct cause of the following exception:

Traceback (most recent call last):
  File "D:\Training\FastAPI\Structural FastAPI\backend\services\category_services.py", line 90, in admin_read_categories
    category_data = category_dao.read_categories()
  File "D:\Training\FastAPI\Structural FastAPI\backend\dao\category_dao.py", line 22, in read_categories
    category_data = sql_dynamic.view_data_all('category_table')
  File "D:\Training\FastAPI\Structural FastAPI\backend\sql_dynamic.py", line 48, in view_data_all
    db.refresh(view_stmt)
  File "C:\ProgramData\Anaconda3\lib\site-packages\sqlalchemy\orm\session.py", line 3130, in refresh
    raise exc.UnmappedInstanceError(instance) from err
sqlalchemy.orm.exc.UnmappedInstanceError: Class 'builtins.list' is not mapped
2024-07-29 16:32:14,259 - backend.services.category_services - ERROR - Category Read Service Exception: Class 'builtins.list' is not mapped
Traceback (most recent call last):
  File "C:\ProgramData\Anaconda3\lib\site-packages\sqlalchemy\orm\session.py", line 3128, in refresh
    state = attributes.instance_state(instance)
AttributeError: 'list' object has no attribute '_sa_instance_state'

The above exception was the direct cause of the following exception:

Traceback (most recent call last):
  File "D:\Training\FastAPI\Structural FastAPI\backend\services\category_services.py", line 90, in admin_read_categories
    category_data = category_dao.read_categories()
  File "D:\Training\FastAPI\Structural FastAPI\backend\dao\category_dao.py", line 22, in read_categories
    category_data = sql_dynamic.view_data_all('category_table')
  File "D:\Training\FastAPI\Structural FastAPI\backend\sql_dynamic.py", line 48, in view_data_all
    db.refresh(view_stmt)
  File "C:\ProgramData\Anaconda3\lib\site-packages\sqlalchemy\orm\session.py", line 3130, in refresh
    raise exc.UnmappedInstanceError(instance) from err
sqlalchemy.orm.exc.UnmappedInstanceError: Class 'builtins.list' is not mapped
2024-07-29 17:06:38,317 - backend.services.category_services - ERROR - Category Delete Service Exception: can't set attribute
Traceback (most recent call last):
  File "D:\Training\FastAPI\Structural FastAPI\backend\services\category_services.py", line 136, in admin_delete_category
    category_vo_list.is_deleted = True
  File "C:\ProgramData\Anaconda3\lib\site-packages\sqlalchemy\engine\row.py", line 81, in __setattr__
    raise AttributeError("can't set attribute")
AttributeError: can't set attribute
